<robot name="THex_Quadruped">

    <mujoco>
        <compiler meshdir="meshes/" discardvisual="false"/>
    </mujoco>

    <link name="base_link">
        <inertial>
            <mass value="0.30423"/>
            <origin xyz="-1.0171e-10 -0.0086065 0.03608" rpy="0 -0 0"/>
            <inertia ixx="0.00232" ixy="0" ixz="0" iyy="0.00064" iyz="8e-05" izz="0.00225"/>
        </inertial>
        <visual>
            <origin xyz="0 0 0" rpy="0 -0 0"/>
            <geometry>
                <mesh filename="meshes/base_link.STL" scale="1 1 1"/>
            </geometry>
            <material name="base_linkbase_link_visual">
                <color rgba="1.0 1.0 1.0 1.0"/>
            </material>
        </visual>
        <collision>
            <origin xyz="0 0 0" rpy="0 -0 0"/>
            <geometry>
                <mesh filename="meshes/base_link_collision.STL" scale="1 1 1"/>
            </geometry>
        </collision>
    </link>
    <link name="bl_foot">
        <inertial>
            <mass value="0.09125"/>
            <origin xyz="0.021142 0.0035788 -0.0013921" rpy="-2.35926e-33 1.11022e-16 -4.25007e-17"/>
            <inertia ixx="1e-05" ixy="0" ixz="0" iyy="4e-05" iyz="0" izz="4e-05"/>
        </inertial>
        <visual>
            <origin xyz="-2.22045e-16 -2.77556e-16 1.2326e-32" rpy="-9.43706e-33 2.22045e-16 -8.50015e-17"/>
            <geometry>
                <mesh filename="meshes/bl_foot.STL" scale="1 1 1"/>
            </geometry>
            <material name="bl_footbl_foot_visual">
                <color rgba="1.0 1.0 1.0 1.0"/>
            </material>
        </visual>
        <collision>
            <origin xyz="-2.22045e-16 -2.77556e-16 1.2326e-32" rpy="-9.43706e-33 2.22045e-16 -8.50015e-17"/>
            <geometry>
                <mesh filename="meshes/bl_foot_collision.STL" scale="1 1 1"/>
            </geometry>
        </collision>
    </link>
    <link name="bl_hip">
        <inertial>
            <mass value="0.14763"/>
            <origin xyz="0.015013 -0.0039618 0.012299" rpy="0 -0 0"/>
            <inertia ixx="5e-05" ixy="1e-05" ixz="-1e-05" iyy="5e-05" iyz="0" izz="6e-05"/>
        </inertial>
        <visual>
            <origin xyz="1.11022e-16 1.38778e-16 0" rpy="0 -0 0"/>
            <geometry>
                <mesh filename="meshes/bl_hip.STL" scale="1 1 1"/>
            </geometry>
            <material name="bl_hipbl_hip_visual">
                <color rgba="1.0 1.0 1.0 1.0"/>
            </material>
        </visual>
        <collision>
            <origin xyz="1.11022e-16 1.38778e-16 0" rpy="0 -0 0"/>
            <geometry>
                <mesh filename="meshes/bl_hip_collision.STL" scale="1 1 1"/>
            </geometry>
        </collision>
    </link>
    <link name="bl_knee">
        <inertial>
            <mass value="0.03468"/>
            <origin xyz="0.045291 0.0044813 -0.0012523" rpy="0 -5.55112e-17 0"/>
            <inertia ixx="2e-05" ixy="0" ixz="0" iyy="3e-05" iyz="0" izz="2e-05"/>
        </inertial>
        <visual>
            <origin xyz="5.55112e-17 2.77556e-17 -1.38778e-17" rpy="0 -1.11022e-16 0"/>
            <geometry>
                <mesh filename="meshes/bl_knee.STL" scale="1 1 1"/>
            </geometry>
            <material name="bl_kneebl_knee_visual">
                <color rgba="1.0 1.0 1.0 1.0"/>
            </material>
        </visual>
        <collision>
            <origin xyz="5.55112e-17 2.77556e-17 -1.38778e-17" rpy="0 -1.11022e-16 0"/>
            <geometry>
                <mesh filename="meshes/bl_knee_collision.STL" scale="1 1 1"/>
            </geometry>
        </collision>
    </link>
    <link name="br_foot">
        <inertial>
            <mass value="0.09125"/>
            <origin xyz="0.020857 -0.003581 -0.0013921" rpy="-4.33681e-19 1.77809e-17 1.82146e-17"/>
            <inertia ixx="1e-05" ixy="0" ixz="0" iyy="4e-05" iyz="0" izz="4e-05"/>
        </inertial>
        <visual>
            <origin xyz="5.55112e-17 5.55112e-17 -5.05557e-34" rpy="-8.67362e-19 3.55618e-17 3.64292e-17"/>
            <geometry>
                <mesh filename="meshes/br_foot.STL" scale="1 1 1"/>
            </geometry>
            <material name="br_footbr_foot_visual">
                <color rgba="1.0 1.0 1.0 1.0"/>
            </material>
        </visual>
        <collision>
            <origin xyz="5.55112e-17 5.55112e-17 -5.05557e-34" rpy="-8.67362e-19 3.55618e-17 3.64292e-17"/>
            <geometry>
                <mesh filename="meshes/br_foot_collision.STL" scale="1 1 1"/>
            </geometry>
        </collision>
    </link>
    <link name="br_hip">
        <inertial>
            <mass value="0.14763"/>
            <origin xyz="0.014987 0.0036918 0.011971" rpy="0 -0 0"/>
            <inertia ixx="5e-05" ixy="-1e-05" ixz="-1e-05" iyy="5e-05" iyz="0" izz="6e-05"/>
        </inertial>
        <visual>
            <origin xyz="-5.55112e-17 2.77556e-17 -2.1684e-19" rpy="0 -0 0"/>
            <geometry>
                <mesh filename="meshes/br_hip.STL" scale="1 1 1"/>
            </geometry>
            <material name="br_hipbr_hip_visual">
                <color rgba="1.0 1.0 1.0 1.0"/>
            </material>
        </visual>
        <collision>
            <origin xyz="-5.55112e-17 2.77556e-17 -2.1684e-19" rpy="0 -0 0"/>
            <geometry>
                <mesh filename="meshes/br_hip_collision.STL" scale="1 1 1"/>
            </geometry>
        </collision>
    </link>
    <link name="br_knee">
        <inertial>
            <mass value="0.03468"/>
            <origin xyz="0.045283 -0.0044813 -0.0010646" rpy="4.62223e-33 -1.66533e-16 -5.55112e-17"/>
            <inertia ixx="2e-05" ixy="0" ixz="0" iyy="3e-05" iyz="0" izz="2e-05"/>
        </inertial>
        <visual>
            <origin xyz="1.11022e-16 9.71445e-17 -1.38778e-17" rpy="1.84889e-32 -3.33067e-16 -1.11022e-16"/>
            <geometry>
                <mesh filename="meshes/br_knee.STL" scale="1 1 1"/>
            </geometry>
            <material name="br_kneebr_knee_visual">
                <color rgba="1.0 1.0 1.0 1.0"/>
            </material>
        </visual>
        <collision>
            <origin xyz="1.11022e-16 9.71445e-17 -1.38778e-17" rpy="1.84889e-32 -3.33067e-16 -1.11022e-16"/>
            <geometry>
                <mesh filename="meshes/br_knee_collision.STL" scale="1 1 1"/>
            </geometry>
        </collision>
    </link>
    <link name="fl_foot">
        <inertial>
            <mass value="0.09125"/>
            <origin xyz="0.021142 0.0035788 -0.0013921" rpy="1.27593e-33 -4.59702e-17 -5.55112e-17"/>
            <inertia ixx="1e-05" ixy="0" ixz="0" iyy="4e-05" iyz="0" izz="4e-05"/>
        </inertial>
        <visual>
            <origin xyz="-1.11022e-16 3.08149e-33 -2.55186e-33" rpy="5.10371e-33 -9.19403e-17 -1.11022e-16"/>
            <geometry>
                <mesh filename="meshes/fl_foot.STL" scale="1 1 1"/>
            </geometry>
            <material name="fl_footfl_foot_visual">
                <color rgba="1.0 1.0 1.0 1.0"/>
            </material>
        </visual>
        <collision>
            <origin xyz="-1.11022e-16 3.08149e-33 -2.55186e-33" rpy="5.10371e-33 -9.19403e-17 -1.11022e-16"/>
            <geometry>
                <mesh filename="meshes/fl_foot_collision.STL" scale="1 1 1"/>
            </geometry>
        </collision>
    </link>
    <link name="fl_hip">
        <inertial>
            <mass value="0.14763"/>
            <origin xyz="0.015006 0.0056423 0.012299" rpy="0 -0 0"/>
            <inertia ixx="5e-05" ixy="-1e-05" ixz="-1e-05" iyy="5e-05" iyz="0" izz="6e-05"/>
        </inertial>
        <visual>
            <origin xyz="-2.77556e-17 -1.38778e-17 0" rpy="0 -0 0"/>
            <geometry>
                <mesh filename="meshes/fl_hip.STL" scale="1 1 1"/>
            </geometry>
            <material name="fl_hipfl_hip_visual">
                <color rgba="1.0 1.0 1.0 1.0"/>
            </material>
        </visual>
        <collision>
            <origin xyz="-2.77556e-17 -1.38778e-17 0" rpy="0 -0 0"/>
            <geometry>
                <mesh filename="meshes/fl_hip_collision.STL" scale="1 1 1"/>
            </geometry>
        </collision>
    </link>
    <link name="fl_knee">
        <inertial>
            <mass value="0.034681"/>
            <origin xyz="0.045273 0.0044813 -0.00044769" rpy="0 -5.55112e-17 0"/>
            <inertia ixx="2e-05" ixy="0" ixz="0" iyy="3e-05" iyz="0" izz="2e-05"/>
        </inertial>
        <visual>
            <origin xyz="-5.55112e-17 3.46945e-17 -1.54074e-33" rpy="0 -1.11022e-16 0"/>
            <geometry>
                <mesh filename="meshes/fl_knee.STL" scale="1 1 1"/>
            </geometry>
            <material name="fl_kneefl_knee_visual">
                <color rgba="1.0 1.0 1.0 1.0"/>
            </material>
        </visual>
        <collision>
            <origin xyz="-5.55112e-17 3.46945e-17 -1.54074e-33" rpy="0 -1.11022e-16 0"/>
            <geometry>
                <mesh filename="meshes/fl_knee_collision.STL" scale="1 1 1"/>
            </geometry>
        </collision>
    </link>
    <link name="fr_foot">
        <inertial>
            <mass value="0.09125"/>
            <origin xyz="0.020857 -0.003581 -0.0013921" rpy="0 -0 5.55112e-17"/>
            <inertia ixx="1e-05" ixy="0" ixz="0" iyy="4e-05" iyz="0" izz="4e-05"/>
        </inertial>
        <visual>
            <origin xyz="-1.11022e-16 -3.08149e-33 -1.38778e-17" rpy="0 -0 1.11022e-16"/>
            <geometry>
                <mesh filename="meshes/fr_foot.STL" scale="1 1 1"/>
            </geometry>
            <material name="fr_footfr_foot_visual">
                <color rgba="1.0 1.0 1.0 1.0"/>
            </material>
        </visual>
        <collision>
            <origin xyz="-1.11022e-16 -3.08149e-33 -1.38778e-17" rpy="0 -0 1.11022e-16"/>
            <geometry>
                <mesh filename="meshes/fr_foot_collision.STL" scale="1 1 1"/>
            </geometry>
        </collision>
    </link>
    <link name="fr_hip">
        <inertial>
            <mass value="0.14763"/>
            <origin xyz="0.015044 -0.0059121 0.011971" rpy="0 -0 0"/>
            <inertia ixx="5e-05" ixy="1e-05" ixz="-1e-05" iyy="5e-05" iyz="0" izz="6e-05"/>
        </inertial>
        <visual>
            <origin xyz="0 0 0" rpy="0 -0 0"/>
            <geometry>
                <mesh filename="meshes/fr_hip.STL" scale="1 1 1"/>
            </geometry>
            <material name="fr_hipfr_hip_visual">
                <color rgba="1.0 1.0 1.0 1.0"/>
            </material>
        </visual>
        <collision>
            <origin xyz="0 0 0" rpy="0 -0 0"/>
            <geometry>
                <mesh filename="meshes/fr_hip_collision.STL" scale="1 1 1"/>
            </geometry>
        </collision>
    </link>
    <link name="fr_knee">
        <inertial>
            <mass value="0.03468"/>
            <origin xyz="0.045275 -0.0044813 -0.00025994" rpy="0 -5.55112e-17 0"/>
            <inertia ixx="2e-05" ixy="0" ixz="0" iyy="3e-05" iyz="0" izz="2e-05"/>
        </inertial>
        <visual>
            <origin xyz="-7.70372e-34 3.46945e-17 2.77556e-17" rpy="0 -1.11022e-16 0"/>
            <geometry>
                <mesh filename="meshes/fr_knee.STL" scale="1 1 1"/>
            </geometry>
            <material name="fr_kneefr_knee_visual">
                <color rgba="1.0 1.0 1.0 1.0"/>
            </material>
        </visual>
        <collision>
            <origin xyz="-7.70372e-34 3.46945e-17 2.77556e-17" rpy="0 -1.11022e-16 0"/>
            <geometry>
                <mesh filename="meshes/fr_knee_collision.STL" scale="1 1 1"/>
            </geometry>
        </collision>
    </link>
    <joint name="bl_foot_joint" type="revolute">
        <origin xyz="0.073069 0.018656 -0.00019751" rpy="3.134 0.0073895 0.7853"/>
        <axis xyz="1.11022e-16 -2.35926e-33 1"/>
        <parent link="bl_knee"/>
        <child link="bl_foot"/>
        <dynamics damping="0" friction="0"/>
        <limit effort="0.9414" velocity="5.23" lower="-1.5707" upper="1.5707"/>
    </joint>
    <joint name="bl_hip_joint" type="revolute">
        <origin xyz="-0.053162 -0.12711 0" rpy="0 0 -2.372"/>
        <axis xyz="0 0 1"/>
        <parent link="base_link"/>
        <child link="bl_hip"/>
        <dynamics damping="0" friction="0"/>
        <limit effort="0.9414" velocity="5.23" lower="-0.7853" upper="0.7853"/>
    </joint>
    <joint name="bl_knee_joint" type="revolute">
        <origin xyz="0.028451 6.245e-17 0" rpy="-1.5602 0 0"/>
        <axis xyz="-5.55112e-17 0 1"/>
        <parent link="bl_hip"/>
        <child link="bl_knee"/>
        <dynamics damping="0" friction="0"/>
        <limit effort="0.9414" velocity="5.23" lower="-1.5707" upper="1.5707"/>
    </joint>
    <joint name="br_foot_joint" type="revolute">
        <origin xyz="0.073065 -0.018656 -0.0001221" rpy="-3.1369 0.0045678 -0.7853"/>
        <axis xyz="1.77809e-17 4.33681e-19 1"/>
        <parent link="br_knee"/>
        <child link="br_foot"/>
        <dynamics damping="0" friction="0"/>
        <limit effort="0.9414" velocity="5.23" lower="-1.5707" upper="1.5707"/>
    </joint>
    <joint name="br_hip_joint" type="revolute">
        <origin xyz="0.053162 -0.12711 0.0005334" rpy="0 0 -0.77529"/>
        <axis xyz="0 0 1"/>
        <parent link="base_link"/>
        <child link="br_hip"/>
        <dynamics damping="0" friction="0"/>
        <limit effort="0.9414" velocity="5.23" lower="-0.7853" upper="0.7853"/>
    </joint>
    <joint name="br_knee_joint" type="revolute">
        <origin xyz="0.028449 -6.93889e-18 -1.0842e-19" rpy="1.5643 -0 0"/>
        <axis xyz="-1.66533e-16 4.62223e-33 1"/>
        <parent link="br_hip"/>
        <child link="br_knee"/>
        <dynamics damping="0" friction="0"/>
        <limit effort="0.9414" velocity="5.23" lower="-1.5707" upper="1.5707"/>
    </joint>
    <joint name="fl_foot_joint" type="revolute">
        <origin xyz="0.073066 0.018656 0.00012569" rpy="-3.1368 -0.0047025 0.7853"/>
        <axis xyz="-4.59702e-17 1.27593e-33 1"/>
        <parent link="fl_knee"/>
        <child link="fl_foot"/>
        <dynamics damping="0" friction="0"/>
        <limit effort="0.9414" velocity="5.23" lower="-1.5707" upper="1.5707"/>
    </joint>
    <joint name="fl_hip_joint" type="revolute">
        <origin xyz="-0.059512 0.078854 0" rpy="0 -0 2.3666"/>
        <axis xyz="0 0 1"/>
        <parent link="base_link"/>
        <child link="fl_hip"/>
        <dynamics damping="0" friction="0"/>
        <limit effort="0.9414" velocity="5.23" lower="-0.7853" upper="0.7853"/>
    </joint>
    <joint name="fl_knee_joint" type="revolute">
        <origin xyz="0.028449 -6.93889e-18 0" rpy="-1.5775 3.93837e-17 3.91205e-17"/>
        <axis xyz="-5.55112e-17 0 1"/>
        <parent link="fl_hip"/>
        <child link="fl_knee"/>
        <dynamics damping="0" friction="0"/>
        <limit effort="0.9414" velocity="5.23" lower="-1.5707" upper="1.5707"/>
    </joint>
    <joint name="fr_foot_joint" type="revolute">
        <origin xyz="0.07307 -0.018656 0.0002011" rpy="3.1339 -0.0075232 -0.7853"/>
        <axis xyz="0 0 1"/>
        <parent link="fr_knee"/>
        <child link="fr_foot"/>
        <dynamics damping="0" friction="0"/>
        <limit effort="0.9414" velocity="5.23" lower="-1.5707" upper="1.5707"/>
    </joint>
    <joint name="fr_hip_joint" type="revolute">
        <origin xyz="0.059512 0.078854 0.0005334" rpy="0 -0 0.76931"/>
        <axis xyz="0 0 1"/>
        <parent link="base_link"/>
        <child link="fr_hip"/>
        <dynamics damping="0" friction="0"/>
        <limit effort="0.9414" velocity="5.23" lower="-0.7853" upper="0.7853"/>
    </joint>
    <joint name="fr_knee_joint" type="revolute">
        <origin xyz="0.028451 -6.93889e-18 0" rpy="1.5816 -3.94638e-17 3.90397e-17"/>
        <axis xyz="-5.55112e-17 0 1"/>
        <parent link="fr_hip"/>
        <child link="fr_knee"/>
        <dynamics damping="0" friction="0"/>
        <limit effort="0.9414" velocity="5.23" lower="-1.5707" upper="1.5707"/>
    </joint>

    <ros2_control name="GazeboSimSystem" type="system">
      <hardware>
        <plugin>gz_ros2_control/GazeboSimSystem</plugin>
      </hardware>

      <joint name="fl_hip_joint">
        <command_interface name="position"/>
        <state_interface name="position"/>
        <param name="p">5.0</param><param name="i">0.0</param><param name="d">0.1</param>
      </joint>
      <joint name="fl_knee_joint">
        <command_interface name="position"/>
        <state_interface name="position"/>
        <param name="p">5.0</param><param name="i">0.0</param><param name="d">0.1</param>
      </joint>
      <joint name="fl_foot_joint">
        <command_interface name="position"/>
        <state_interface name="position"/>
        <param name="p">5.0</param><param name="i">0.0</param><param name="d">0.1</param>
      </joint>

      <joint name="fr_hip_joint">
        <command_interface name="position"/>
        <state_interface name="position"/>
        <param name="p">5.0</param><param name="i">0.0</param><param name="d">0.1</param>
      </joint>
      <joint name="fr_knee_joint">
        <command_interface name="position"/>
        <state_interface name="position"/>
        <param name="p">5.0</param><param name="i">0.0</param><param name="d">0.1</param>
      </joint>
      <joint name="fr_foot_joint">
        <command_interface name="position"/>
        <state_interface name="position"/>
        <param name="p">5.0</param><param name="i">0.0</param><param name="d">0.1</param>
      </joint>

      <joint name="bl_hip_joint">
        <command_interface name="position"/>
        <state_interface name="position"/>
        <param name="p">5.0</param><param name="i">0.0</param><param name="d">0.1</param>
      </joint>
      <joint name="bl_knee_joint">
        <command_interface name="position"/>
        <state_interface name="position"/>
        <param name="p">5.0</param><param name="i">0.0</param><param name="d">0.1</param>
      </joint>
      <joint name="bl_foot_joint">
        <command_interface name="position"/>
        <state_interface name="position"/>
        <param name="p">5.0</param><param name="i">0.0</param><param name="d">0.1</param>
      </joint>

      <joint name="br_hip_joint">
        <command_interface name="position"/>
        <state_interface name="position"/>
        <param name="p">5.0</param><param name="i">0.0</param><param name="d">0.1</param>
      </joint>
      <joint name="br_knee_joint">
        <command_interface name="position"/>
        <state_interface name="position"/>
        <param name="p">5.0</param><param name="i">0.0</param><param name="d">0.1</param>
      </joint>
      <joint name="br_foot_joint">
        <command_interface name="position"/>
        <state_interface name="position"/>
        <param name="p">5.0</param><param name="i">0.0</param><param name="d">0.1</param>
      </joint>
    </ros2_control>

    <gazebo>
      <plugin filename="gz_ros2_control-system" name="gz_ros2_control::GazeboSimROS2ControlPlugin">
        <parameters>$(find_pkg_share rl_ros2)/config/controllers.yaml</parameters>
      </plugin>
    </gazebo>

    <gazebo reference="base_link">
      <sensor name="imu_sensor" type="imu">
        <always_on>1</always_on>
        <update_rate>50</update_rate>
        <visualize>true</visualize>
        <topic>imu</topic>
      </sensor>
    </gazebo>
</robot>
