<mujoco model="THex_Quadruped">
  <compiler angle="radian" />

  <asset>
    <mesh name="base_link" content_type="model/stl" file="meshes/base_link.STL" />
    <mesh name="base_link_collision" content_type="model/stl" file="meshes/base_link_collision.STL" />
    <mesh name="bl_foot" content_type="model/stl" file="meshes/bl_foot.STL" />
    <mesh name="bl_foot_collision" content_type="model/stl" file="meshes/bl_foot_collision.STL" />
    <mesh name="bl_hip" content_type="model/stl" file="meshes/bl_hip.STL" />
    <mesh name="bl_hip_collision" content_type="model/stl" file="meshes/bl_hip_collision.STL" />
    <mesh name="bl_knee" content_type="model/stl" file="meshes/bl_knee.STL" />
    <mesh name="bl_knee_collision" content_type="model/stl" file="meshes/bl_knee_collision.STL" />
    <mesh name="br_foot" content_type="model/stl" file="meshes/br_foot.STL" />
    <mesh name="br_foot_collision" content_type="model/stl" file="meshes/br_foot_collision.STL" />
    <mesh name="br_hip" content_type="model/stl" file="meshes/br_hip.STL" />
    <mesh name="br_hip_collision" content_type="model/stl" file="meshes/br_hip_collision.STL" />
    <mesh name="br_knee" content_type="model/stl" file="meshes/br_knee.STL" />
    <mesh name="br_knee_collision" content_type="model/stl" file="meshes/br_knee_collision.STL" />
    <mesh name="fl_foot" content_type="model/stl" file="meshes/fl_foot.STL" />
    <mesh name="fl_foot_collision" content_type="model/stl" file="meshes/fl_foot_collision.STL" />
    <mesh name="fl_hip" content_type="model/stl" file="meshes/fl_hip.STL" />
    <mesh name="fl_hip_collision" content_type="model/stl" file="meshes/fl_hip_collision.STL" />
    <mesh name="fl_knee" content_type="model/stl" file="meshes/fl_knee.STL" />
    <mesh name="fl_knee_collision" content_type="model/stl" file="meshes/fl_knee_collision.STL" />
    <mesh name="fr_foot" content_type="model/stl" file="meshes/fr_foot.STL" />
    <mesh name="fr_foot_collision" content_type="model/stl" file="meshes/fr_foot_collision.STL" />
    <mesh name="fr_hip" content_type="model/stl" file="meshes/fr_hip.STL" />
    <mesh name="fr_hip_collision" content_type="model/stl" file="meshes/fr_hip_collision.STL" />
    <mesh name="fr_knee" content_type="model/stl" file="meshes/fr_knee.STL" />
    <mesh name="fr_knee_collision" content_type="model/stl" file="meshes/fr_knee_collision.STL" />
  </asset>

  <worldbody>
    <body name="base_link" pos="0 0 0.3"><freejoint name="base_freejoint" /><inertial pos="-1.0171e-10 -0.0086065 0.03608" mass="0.30423" fullinertia="0.00232 0.00064 0.00225 0.0 0.0 8e-05" /><geom type="mesh" contype="0" conaffinity="0" group="1" density="0" rgba="0.7 0.7 0.75 1.0" mesh="base_link" />
    <geom type="mesh" rgba="1 1 1 1" mesh="base_link_collision" contype="1" conaffinity="1" />
    <body name="bl_hip" pos="-0.053162 -0.12711 0" quat="0.37537 0 0 -0.926875">
      <inertial pos="0.015013 -0.0039618 0.012299" quat="2.44234e-10 0.452212 -0.362646 0.814857" mass="0.14763" diaginertia="6.80194e-05 5.44504e-05 3.75302e-05" />
      <joint name="bl_hip_joint" pos="0 0 0" axis="0 0 1" range="-0.7853 0.7853" actuatorfrcrange="-0.9414 0.9414" />
      <geom type="mesh" contype="0" conaffinity="0" group="1" density="0" rgba="0.7 0.7 0.75 1.0" mesh="bl_hip" />
      <geom type="mesh" rgba="1 1 1 1" mesh="bl_hip_collision" contype="1" conaffinity="1" />
      <body name="bl_knee" pos="0.028451 0 0" quat="0.710843 -0.703351 0 0">
        <inertial pos="0.045291 0.0044813 -0.0012523" quat="0.707107 0 0 0.707107" mass="0.03468" diaginertia="3e-05 2e-05 2e-05" />
        <joint name="bl_knee_joint" pos="0 0 0" axis="0 0 1" range="-1.5707 1.5707" actuatorfrcrange="-0.9414 0.9414" />
        <geom type="mesh" contype="0" conaffinity="0" group="1" density="0" rgba="0.7 0.7 0.75 1.0" mesh="bl_knee" />
        <geom type="mesh" rgba="1 1 1 1" mesh="bl_knee_collision" contype="1" conaffinity="1" />
        <body name="bl_foot" pos="0.073069 0.018656 -0.00019751" quat="0.00492113 0.92388 0.382646 -0.00196094">
          <inertial pos="0.021142 0.0035788 -0.0013921" quat="0.5 0.5 0.5 0.5" mass="0.09125" diaginertia="4e-05 4e-05 1e-05" />
          <joint name="bl_foot_joint" pos="0 0 0" axis="0 0 1" range="-1.5707 1.5707" actuatorfrcrange="-0.9414 0.9414" />
          <geom pos="0 0 0" quat="1 0 0 0" type="mesh" contype="0" conaffinity="0" group="1" density="0" rgba="0.7 0.7 0.75 1.0" mesh="bl_foot" />
          <geom pos="0 0 0" quat="1 0 0 0" type="mesh" rgba="1 1 1 1" mesh="bl_foot_collision" contype="1" conaffinity="1" />
        </body>
      </body>
    </body>
    <body name="br_hip" pos="0.053162 -0.12711 0.0005334" quat="0.925802 0 0 -0.378009">
      <inertial pos="0.014987 0.0036918 0.011971" quat="-2.44234e-10 0.452212 0.362646 0.814857" mass="0.14763" diaginertia="6.80194e-05 5.44504e-05 3.75302e-05" />
      <joint name="br_hip_joint" pos="0 0 0" axis="0 0 1" range="-0.7853 0.7853" actuatorfrcrange="-0.9414 0.9414" />
      <geom type="mesh" contype="0" conaffinity="0" group="1" density="0" rgba="0.7 0.7 0.75 1.0" mesh="br_hip" />
      <geom type="mesh" rgba="1 1 1 1" mesh="br_hip_collision" contype="1" conaffinity="1" />
      <body name="br_knee" pos="0.028449 0 0" quat="0.7094 0.704806 0 0">
        <inertial pos="0.045283 -0.0044813 -0.0010646" quat="0.707107 0 0 0.707107" mass="0.03468" diaginertia="3e-05 2e-05 2e-05" />
        <joint name="br_knee_joint" pos="0 0 0" axis="0 0 1" range="-1.5707 1.5707" actuatorfrcrange="-0.9414 0.9414" />
        <geom type="mesh" contype="0" conaffinity="0" group="1" density="0" rgba="0.7 0.7 0.75 1.0" mesh="br_knee" />
        <geom type="mesh" rgba="1 1 1 1" mesh="br_knee_collision" contype="1" conaffinity="1" />
        <body name="br_foot" pos="0.073065 -0.018656 -0.0001221" quat="0.00304166 -0.923891 0.382641 0.00121229">
          <inertial pos="0.020857 -0.003581 -0.0013921" quat="0.5 0.5 0.5 0.5" mass="0.09125" diaginertia="4e-05 4e-05 1e-05" />
          <joint name="br_foot_joint" pos="0 0 0" axis="0 0 1" range="-1.5707 1.5707" actuatorfrcrange="-0.9414 0.9414" />
          <geom type="mesh" contype="0" conaffinity="0" group="1" density="0" rgba="0.7 0.7 0.75 1.0" mesh="br_foot" />
          <geom type="mesh" rgba="1 1 1 1" mesh="br_foot_collision" contype="1" conaffinity="1" />
        </body>
      </body>
    </body>
    <body name="fl_hip" pos="-0.059512 0.078854 0" quat="0.377872 0 0 0.925858">
      <inertial pos="0.015006 0.0056423 0.012299" quat="-2.44234e-10 0.452212 0.362646 0.814857" mass="0.14763" diaginertia="6.80194e-05 5.44504e-05 3.75302e-05" />
      <joint name="fl_hip_joint" pos="0 0 0" axis="0 0 1" range="-0.7853 0.7853" actuatorfrcrange="-0.9414 0.9414" />
      <geom type="mesh" contype="0" conaffinity="0" group="1" density="0" rgba="0.7 0.7 0.75 1.0" mesh="fl_hip" />
      <geom type="mesh" rgba="1 1 1 1" mesh="fl_hip_collision" contype="1" conaffinity="1" />
      <body name="fl_knee" pos="0.028449 0 0" quat="0.704733 -0.709473 0 0">
        <inertial pos="0.045273 0.0044813 -0.00044769" quat="0.707107 0 0 0.707107" mass="0.034681" diaginertia="3e-05 2e-05 2e-05" />
        <joint name="fl_knee_joint" pos="0 0 0" axis="0 0 1" range="-1.5707 1.5707" actuatorfrcrange="-0.9414 0.9414" />
        <geom type="mesh" contype="0" conaffinity="0" group="1" density="0" rgba="0.7 0.7 0.75 1.0" mesh="fl_knee" />
        <geom type="mesh" rgba="1 1 1 1" mesh="fl_knee_collision" contype="1" conaffinity="1" />
        <body name="fl_foot" pos="0.073066 0.018656 0.00012569" quat="0.00311363 -0.923891 -0.382641 -0.00125539">
          <inertial pos="0.021142 0.0035788 -0.0013921" quat="0.5 0.5 0.5 0.5" mass="0.09125" diaginertia="4e-05 4e-05 1e-05" />
          <joint name="fl_foot_joint" pos="0 0 0" axis="0 0 1" range="-1.5707 1.5707" actuatorfrcrange="-0.9414 0.9414" />
          <geom type="mesh" contype="0" conaffinity="0" group="1" density="0" rgba="0.7 0.7 0.75 1.0" mesh="fl_foot" />
          <geom type="mesh" rgba="1 1 1 1" mesh="fl_foot_collision" contype="1" conaffinity="1" />
        </body>
      </body>
    </body>
    <body name="fr_hip" pos="0.059512 0.078854 0.0005334" quat="0.926928 0 0 0.375239">
      <inertial pos="0.015044 -0.0059121 0.011971" quat="2.44234e-10 0.452212 -0.362646 0.814857" mass="0.14763" diaginertia="6.80194e-05 5.44504e-05 3.75302e-05" />
      <joint name="fr_hip_joint" pos="0 0 0" axis="0 0 1" range="-0.7853 0.7853" actuatorfrcrange="-0.9414 0.9414" />
      <geom type="mesh" contype="0" conaffinity="0" group="1" density="0" rgba="0.7 0.7 0.75 1.0" mesh="fr_hip" />
      <geom type="mesh" rgba="1 1 1 1" mesh="fr_hip_collision" contype="1" conaffinity="1" />
      <body name="fr_knee" pos="0.028451 0 0" quat="0.703277 0.710916 0 0">
        <inertial pos="0.045275 -0.0044813 -0.00025994" quat="0.707107 0 0 0.707107" mass="0.03468" diaginertia="3e-05 2e-05 2e-05" />
        <joint name="fr_knee_joint" pos="0 0 0" axis="0 0 1" range="-1.5707 1.5707" actuatorfrcrange="-0.9414 0.9414" />
        <geom type="mesh" contype="0" conaffinity="0" group="1" density="0" rgba="0.7 0.7 0.75 1.0" mesh="fr_knee" />
        <geom type="mesh" rgba="1 1 1 1" mesh="fr_knee_collision" contype="1" conaffinity="1" />
        <body name="fr_foot" pos="0.07307 -0.018656 0.0002011" quat="0.0049929 0.923879 -0.382646 0.00200356">
          <inertial pos="0.020857 -0.003581 -0.0013921" quat="0.5 0.5 0.5 0.5" mass="0.09125" diaginertia="4e-05 4e-05 1e-05" />
          <joint name="fr_foot_joint" pos="0 0 0" axis="0 0 1" range="-1.5707 1.5707" actuatorfrcrange="-0.9414 0.9414" />
          <geom type="mesh" contype="0" conaffinity="0" group="1" density="0" rgba="0.7 0.7 0.75 1.0" mesh="fr_foot" />
          <geom type="mesh" rgba="1 1 1 1" mesh="fr_foot_collision" contype="1" conaffinity="1" />
        </body>
      </body>
    </body>
  </body></worldbody>
<actuator><position name="bl_hip_motor" joint="bl_hip_joint" kp="5.0" kv="0.1" ctrlrange="-0.7853 0.7853" forcerange="-0.9414 0.9414" /><position name="bl_knee_motor" joint="bl_knee_joint" kp="5.0" kv="0.1" ctrlrange="-1.5707 1.5707" forcerange="-0.9414 0.9414" /><position name="bl_foot_motor" joint="bl_foot_joint" kp="5.0" kv="0.1" ctrlrange="-1.5707 1.5707" forcerange="-0.9414 0.9414" /><position name="br_hip_motor" joint="br_hip_joint" kp="5.0" kv="0.1" ctrlrange="-0.7853 0.7853" forcerange="-0.9414 0.9414" /><position name="br_knee_motor" joint="br_knee_joint" kp="5.0" kv="0.1" ctrlrange="-1.5707 1.5707" forcerange="-0.9414 0.9414" /><position name="br_foot_motor" joint="br_foot_joint" kp="5.0" kv="0.1" ctrlrange="-1.5707 1.5707" forcerange="-0.9414 0.9414" /><position name="fl_hip_motor" joint="fl_hip_joint" kp="5.0" kv="0.1" ctrlrange="-0.7853 0.7853" forcerange="-0.9414 0.9414" /><position name="fl_knee_motor" joint="fl_knee_joint" kp="5.0" kv="0.1" ctrlrange="-1.5707 1.5707" forcerange="-0.9414 0.9414" /><position name="fl_foot_motor" joint="fl_foot_joint" kp="5.0" kv="0.1" ctrlrange="-1.5707 1.5707" forcerange="-0.9414 0.9414" /><position name="fr_hip_motor" joint="fr_hip_joint" kp="5.0" kv="0.1" ctrlrange="-0.7853 0.7853" forcerange="-0.9414 0.9414" /><position name="fr_knee_motor" joint="fr_knee_joint" kp="5.0" kv="0.1" ctrlrange="-1.5707 1.5707" forcerange="-0.9414 0.9414" /><position name="fr_foot_motor" joint="fr_foot_joint" kp="5.0" kv="0.1" ctrlrange="-1.5707 1.5707" forcerange="-0.9414 0.9414" /></actuator></mujoco>